Workbook

Sheet Cserepes + korcolt
A1: ELŐLEG | F1: Megrendelő
F2: Telefonszám
A3: VÉGÖSSZEG | F3: Szállítási cím
A4: Lemez | C4: Szín | D4: Felület | F4: Vastagság | G4: FILC! | H4: Nettó m2/egységár | J4: RSZ
B6: Teljes szélesség (m) | C6: Hosszúság (m) | D6: Db | E6: m2 összesen | F6: Egységár (nettó) | G6: Összesen (nettó) | H6: Összesen (bruttó) | J6: Rendelés dátuma
A7: 1. | B7: =VLOOKUP($A$5,'Cserepes adatok'!$A$2:$B$9,2,FALSE) -> #N/A | E7: =B7*C7*D7 -> #N/A | F7: =$H$5 -> 0 | G7: =E7*F7 -> #N/A | H7: =G7*1.27 -> #N/A
A8: 2. | B8: =VLOOKUP($A$5,'Cserepes adatok'!$A$2:$B$9,2,FALSE) -> #N/A | E8: =B8*C8*D8 -> #N/A | F8: =$H$5 -> 0 | G8: =E8*F8 -> #N/A | H8: =G8*1.27 -> #N/A
A9: 3. | B9: =VLOOKUP($A$5,'Cserepes adatok'!$A$2:$B$9,2,FALSE) -> #N/A | E9: =B9*C9*D9 -> #N/A | F9: =$H$5 -> 0 | G9: =E9*F9 -> #N/A | H9: =G9*1.27 -> #N/A
A10: 4. | B10: =VLOOKUP($A$5,'Cserepes adatok'!$A$2:$B$9,2,FALSE) -> #N/A | E10: =B10*C10*D10 -> #N/A | F10: =$H$5 -> 0 | G10: =E10*F10 -> #N/A | H10: =G10*1.27 -> #N/A
A11: 5. | B11: =VLOOKUP($A$5,'Cserepes adatok'!$A$2:$B$9,2,FALSE) -> #N/A | E11: =B11*C11*D11 -> #N/A | F11: =$H$5 -> 0 | G11: =E11*F11 -> #N/A | H11: =G11*1.27 -> #N/A
A12: 6. | B12: =VLOOKUP($A$5,'Cserepes adatok'!$A$2:$B$9,2,FALSE) -> #N/A | E12: =B12*C12*D12 -> #N/A | F12: =$H$5 -> 0 | G12: =E12*F12 -> #N/A | H12: =G12*1.27 -> #N/A
A13: 7. | B13: =VLOOKUP($A$5,'Cserepes adatok'!$A$2:$B$9,2,FALSE) -> #N/A | E13: =B13*C13*D13 -> #N/A | F13: =$H$5 -> 0 | G13: =E13*F13 -> #N/A | H13: =G13*1.27 -> #N/A
A14: 8. | B14: =VLOOKUP($A$5,'Cserepes adatok'!$A$2:$B$9,2,FALSE) -> #N/A | E14: =B14*C14*D14 -> #N/A | F14: =$H$5 -> 0 | G14: =E14*F14 -> #N/A | H14: =G14*1.27 -> #N/A
A15: 9. | B15: =VLOOKUP($A$5,'Cserepes adatok'!$A$2:$B$9,2,FALSE) -> #N/A | E15: =B15*C15*D15 -> #N/A | F15: =$H$5 -> 0 | G15: =E15*F15 -> #N/A | H15: =G15*1.27 -> #N/A
A16: 10. | B16: =VLOOKUP($A$5,'Cserepes adatok'!$A$2:$B$9,2,FALSE) -> #N/A | E16: =B16*C16*D16 -> #N/A | F16: =$H$5 -> 0 | G16: =E16*F16 -> #N/A | H16: =G16*1.27 -> #N/A
A17: 11. | B17: =VLOOKUP($A$5,'Cserepes adatok'!$A$2:$B$9,2,FALSE) -> #N/A | E17: =B17*C17*D17 -> #N/A | F17: =$H$5 -> 0 | G17: =E17*F17 -> #N/A | H17: =G17*1.27 -> #N/A
A18: 12. | B18: =VLOOKUP($A$5,'Cserepes adatok'!$A$2:$B$9,2,FALSE) -> #N/A | E18: =B18*C18*D18 -> #N/A | F18: =$H$5 -> 0 | G18: =E18*F18 -> #N/A | H18: =G18*1.27 -> #N/A
... A26: 20. | B26: =VLOOKUP($A$5,'Cserepes adatok'!$A$2:$B$9,2,FALSE) -> #N/A | E26: =B26*C26*D26 -> #N/A | F26: =$H$5 -> 0 | G26: =E26*F26 -> #N/A | H26: =G26*1.27 -> #N/A
B27: ÖSSZESEN: | E27: =SUM(E7:E26) -> #N/A | F27: =$H$5 -> 0 | G27: =E27*F27 -> #N/A | H27: =G27*1.27 -> #N/A
B28: TARTOZÉKOK
B29: Megnevezés | C29: db/m | D29: Egységár (nettó) | F29: Összesen (nettó) | H29: Összesen (bruttó)
B30: Kupás | F30: =C30*D30 -> 0 | H30: =F30*1.27 -> 0
B31: Kupás vég | F31: =C31*D31 -> 0 | H31: =F31*1.27 -> 0
B32: Fa csavar | F32: =C32*D32 -> 0 | H32: =F32*1.27 -> 0
B33: Fém csavar | F33: =C33*D33 -> 0 | H33: =F33*1.27 -> 0
B34: Fűzőcsavar | F34: =C34*D34 -> 0 | H34: =F34*1.27 -> 0
B35: Tetőfólia 130g | F35: =C35*D35 -> 0 | H35: =F35*1.27 -> 0
B36: Vápa | F36: =C36*D36 -> 0 | H36: =F36*1.27 -> 0
B37: Kéményszegő | F37: =C37*D37 -> 0 | H37: =F37*1.27 -> 0
B38: Villanyszegő | F38: =C38*D38 -> 0 | H38: =F38*1.27 -> 0
B39: Hóvágó | F39: =C39*D39 -> 0 | H39: =F39*1.27 -> 0
B40: Kiszállítás | F40: =C40*D40 -> 0 | H40: =F40*1.27 -> 0
B41: ÖSSZESEN: | F41: =SUM(F30:F40) -> 0 | H41: =F41*1.27 -> 0
B42: ÖSSZESEN NETTÓ: | D42: =G27+F41 -> #N/A | F42: ÖSSZESEN (bruttó) | H42: =H27+H41 -> #N/A
B43: Fordított ÁFA
A44: Méretbeli módosításra megrendeléstől számított 2 napon van belül lehetőseg! Ezután a méreteket elfogadottnak tekintjük, így méretek tekintetében reklamációt nem fogadunk el!
A46: Kiszállításnál sofőrünk egyedül megy, ezért a lepakoláshoz segitség szükséges! | F46: ÁRUKIADÁS: | H46: Hétfő - Péntek 7:30 - 16:00 Szombat 07:30 - 12:00
A47: Figyelem! Az útmutatótól eltérő TÁROLÁSBÓL vagy anyagmozgatásból eredő károkért a ReCOPY Kft. (Simai úti lemezkereskedés) nem vállal felelősséget! Tárolási útmutató a hátoldalon!
A49: Szállítási és Tárolási útmutató 1. Megrendelt tételek átvétele A Megrendelő és a Szállító együttesen köteles az áru átadásakor a minőségi és mennyiségi ellenőrzését elvégezni. 1.1. Az árut a Szállító telephelyén a Megrendelő vagy annak meghatalmazottja veszi át az árukiadótól: A megrendelt tételeket a Megrendelő a Szállító árukiadójával együtt köteles a Szállító telephelyén ellenőrizni az átadott áruk minőségét és mennyiségét. Amennyiben eltérést tapasztal a Megrendelő köteles haladéktalanul írásban jelezni a minőségi vagy mennyiségi kifogást a Szállító felé. 1.2. Az árut a Megrendelő vagy az általa meghatalmazottja az előre megjelölt helyen veszi át a Szállító alkalmazottjától: A megrendelt tételeket a Megrendelő a Szállító alkalmazottjával együtt köteles az áru átvételének helyén ellenőrizni az átadott áruk minőségét és mennyiségét. Amennyiben eltérést tapasztal a Megrendelő köteles haladéktalanul írásban jelezni a minőségi vagy mennyiségi kifogást a Szállító felé. 1.3. Az árut egy harmadik fél (pl.: szállítmányozó) veszi át a Szállító telephelyén az árukiadótól: A Megrendelő köteles a harmadik fél által leszállított áruk minőségét és mennyiségét a harmadik féltől való átvétel pillanatában ellenőrizni. Amennyiben eltérést tapasztal a Megrendelő köteles haladéktalanul írásban jelezni a minőségi vagy mennyiségi kifogást a Szállító felé. Az írásban tett mennyiségi kifogást a Szállító kivizsgálja és jogos mennyiségi kifogás esetén, a Szállító köteles a hiányt a jogosság megállapításától számított 30 napon belül pótolni. Az írásban tett minőségi kifogást a Szállító kivizsgálja és jogos minőségi kifogás esetén, a Szállító köteles a kifogásolt minőségi eltérést a jogosság megállapításától számított 30 napon belül kompenzálni vagy visszavásárolni. 2. Szállítás A Szállító által gyártott trapézlemez, cserepeslemez, szendvicspanel, szelemen és síklemez termékek szállítására egyedi szabályok vonatkoznak. A termék szállításának tervezésekor, illetve a termék szállításának megkezdése előtt figyelembe kell venni a szállítási útmutatóban leírt szabályokat. A közzétett szabályoktól való eltérés következtében felmerülő károkért és minőségromlásért a Szállító nem vállal felelősséget. 3. Védőfólia eltávolítása Amennyiben az áru felületét védő fólia védi, akkor a felületén lévő védőfóliát a tárolás megkezdésétől számított négy héten belül, vagy a beépítéstől számított egy héten belül el kell távolítani. 4. Tárolás Az áru kötegeket a helyszínre történő szállítás után nagy körültekintéssel és az alábbi szabályok betartásával lehet úgy tárolni a felszerelésig, hogy az áru minősége ne romoljon. A következő szabályoktól való eltérés esetén, a tárolásból eredő minőségromlásért és kárért a ReCOPYKft. (Simai úti lemezkereskedés) nem vállal felelősséget. 4.1. A kötegeket védeni kell a csapadéktól, a páralecsapódásból eredő nedvesedéstől és általában a nedvességtől. 4.2. A kötegeket enyhén megdöntve kell tárolni, hogy a véletlenül a panel kötegek közé kerülő víz el tudjon folyni a panel felületéről. 4.3. A kötegek egymásra rakhatók, de arra figyelni kell, hogy a kötegeket elválasztó támaszok pontosan egymás felett helyezkedjenek el. Figyelem! A támaszok megnyomhatják az áru felületét. 4.4. A szabad téren tárolt kötegeket vízálló ponyvával kell letakarni úgy, hogy sem a kötegek tetején, sem a kötegek alatt nem gyűlhet össze a csapadékvíz. 4.5. A kötegek számára biztosítani kell az átszellőzést, így kivédhetők a páralecsapódásból eredő nedvesedés okozta károk 5. Javaslatok a helyszínen történő szereléshez A Metál-Sheet Kft. csupán a megrendelt áruk gyártására vállalkozik, nem vesz részt a szerelésben. A szerelésről mindenképpen a vevőnek kell gondoskodni akár saját kivitelezésben, akár szerelésben jártas vállalkozó, vállalkozás igénybe vételével. A Metál-Sheet Kft. az alábbi szabályok betartására hívja fel a figyelmet a szerelés során: 5.1. A kivitelezőnek az összeszerelést meg kell terveznie és a biztonságért felelős személyt ki kell jelölnie. A biztonságos szereléshez szükséges eszközöket, berendezéseket biztosítania kell a helyszínen. 5.2. Amennyiben az árut a helyszínen vágni kell, tilos sarokköszörűt alkalmazni és kerülni kell a vágókorongok alkalmazását is. Javasoljuk a lemezvágó ollót, szalagfűrészt, vagy lengő fűrészt. 5.3. Az áru felületéről minden vágásból, fúrásból eredő törmeléket el kell távolítani, hogy a felülete ne sérüljön. Aláírásommal igazolom, hogy a fentieket elolvastam, tudomásul vettem és elfogadom az azokban leírtakat. Kelt: ............................................................ megrendelő: ...............................

Sheet Trapézlemezek
A1: ELŐLEG | F1: Megrendelő
F2: Telefonszám
A3: VÉGÖSSZEG | F3: Szállítási cím
A4: Lemez | C4: Szín | D4: Felület | F4: Vastagság | G4: FILC! | H4: Nettó m2/egységár | J4: RSZ
A5: T8 Saját gyártású
B6: Teljes szélesség (m) | C6: Hosszúság (m) | D6: Db | E6: m2 összesen | F6: Egységár (nettó) | G6: Összesen (nettó) | H6: Összesen (bruttó) | J6: Rendelés dátuma
A7: 1. | B7: =VLOOKUP($A$5,'Trapéz adatok'!$A$2:$B$17,2,FALSE) -> 1.18 | E7: =B7*C7*D7 -> 0 | F7: =$H$5 -> 0 | G7: =E7*F7 -> 0 | H7: =G7*1.27 -> 0
A8: 2. | B8: =VLOOKUP($A$5,'Trapéz adatok'!$A$2:$B$17,2,FALSE) -> 1.18 | E8: =B8*C8*D8 -> 0 | F8: =$H$5 -> 0 | G8: =E8*F8 -> 0 | H8: =G8*1.27 -> 0
A9: 3. | B9: =VLOOKUP($A$5,'Trapéz adatok'!$A$2:$B$17,2,FALSE) -> 1.18 | E9: =B9*C9*D9 -> 0 | F9: =$H$5 -> 0 | G9: =E9*F9 -> 0 | H9: =G9*1.27 -> 0
A10: 4. | B10: =VLOOKUP($A$5,'Trapéz adatok'!$A$2:$B$17,2,FALSE) -> 1.18 | E10: =B10*C10*D10 -> 0 | F10: =$H$5 -> 0 | G10: =E10*F10 -> 0 | H10: =G10*1.27 -> 0
A11: 5. | B11: =VLOOKUP($A$5,'Trapéz adatok'!$A$2:$B$17,2,FALSE) -> 1.18 | E11: =B11*C11*D11 -> 0 | F11: =$H$5 -> 0 | G11: =E11*F11 -> 0 | H11: =G11*1.27 -> 0
A12: 6. | B12: =VLOOKUP($A$5,'Trapéz adatok'!$A$2:$B$17,2,FALSE) -> 1.18 | E12: =B12*C12*D12 -> 0 | F12: =$H$5 -> 0 | G12: =E12*F12 -> 0 | H12: =G12*1.27 -> 0
A13: 7. | B13: =VLOOKUP($A$5,'Trapéz adatok'!$A$2:$B$17,2,FALSE) -> 1.18 | E13: =B13*C13*D13 -> 0 | F13: =$H$5 -> 0 | G13: =E13*F13 -> 0 | H13: =G13*1.27 -> 0
A14: 8. | B14: =VLOOKUP($A$5,'Trapéz adatok'!$A$2:$B$17,2,FALSE) -> 1.18 | E14: =B14*C14*D14 -> 0 | F14: =$H$5 -> 0 | G14: =E14*F14 -> 0 | H14: =G14*1.27 -> 0
A15: 9. | B15: =VLOOKUP($A$5,'Trapéz adatok'!$A$2:$B$17,2,FALSE) -> 1.18 | E15: =B15*C15*D15 -> 0 | F15: =$H$5 -> 0 | G15: =E15*F15 -> 0 | H15: =G15*1.27 -> 0
A16: 10. | B16: =VLOOKUP($A$5,'Trapéz adatok'!$A$2:$B$17,2,FALSE) -> 1.18 | E16: =B16*C16*D16 -> 0 | F16: =$H$5 -> 0 | G16: =E16*F16 -> 0 | H16: =G16*1.27 -> 0
A17: 11. | B17: =VLOOKUP($A$5,'Trapéz adatok'!$A$2:$B$17,2,FALSE) -> 1.18 | E17: =B17*C17*D17 -> 0 | F17: =$H$5 -> 0 | G17: =E17*F17 -> 0 | H17: =G17*1.27 -> 0
A18: 12. | B18: =VLOOKUP($A$5,'Trapéz adatok'!$A$2:$B$17,2,FALSE) -> 1.18 | E18: =B18*C18*D18 -> 0 | F18: =$H$5 -> 0 | G18: =E18*F18 -> 0 | H18: =G18*1.27 -> 0
... A24: 18. | B24: =VLOOKUP($A$5,'Trapéz adatok'!$A$2:$B$17,2,FALSE) -> 1.18 | E24: =B24*C24*D24 -> 0 | F24: =$H$5 -> 0 | G24: =E24*F24 -> 0 | H24: =G24*1.27 -> 0
B25: ÖSSZESEN: | E25: =SUM(E7:E24) -> 0 | G25: =E25*F25 -> 0 | H25: =G25*1.27 -> 0
B26: TARTOZÉKOK
B27: Megnevezés | C27: db/m | D27: Egységár (nettó) | F27: Összesen (nettó) | H27: Összesen (bruttó)
B28: Kupás | F28: =C28*D28 -> 0 | H28: =F28*1.27 -> 0
B29: Kupás vég | F29: =C29*D29 -> 0 | H29: =F29*1.27 -> 0
B30: Fa csavar | F30: =C30*D30 -> 0 | H30: =F30*1.27 -> 0
B31: Fém csavar | F31: =C31*D31 -> 0 | H31: =F31*1.27 -> 0
B32: Fűző csavar | F32: =C32*D32 -> 0 | H32: =F32*1.27 -> 0
B33: Tetőfólia | F33: =C33*D33 -> 0 | H33: =F33*1.27 -> 0
B34: Tetőkibúvó | F34: =C34*D34 -> 0 | H34: =F34*1.27 -> 0
B35: Kéményszegő | F35: =C35*D35 -> 0 | H35: =F35*1.27 -> 0
B36: Villanyszegő | F36: =C36*D36 -> 0 | H36: =F36*1.27 -> 0
B37: Hóvágó | F37: =C37*D37 -> 0 | H37: =F37*1.27 -> 0
B38: Oromszegő | F38: =C38*D38 -> 0 | H38: =F38*1.27 -> 0
B39: Falszegő | F39: =C39*D39 -> 0 | H39: =F39*1.27 -> 0
... B41: Kiszállítás | F41: =C41*D41 -> 0 | H41: =F41*1.27 -> 0
B42: ÖSSZESEN: | F42: =SUM(F28:F41) -> 0 | H42: =F42*1.27 -> 0
B43: ÖSSZESEN NETTÓ: | D43: =G25+F42 -> 0 | F43: ÖSSZESEN (bruttó) | H43: =H25+H42 -> 0
B44: Fordított ÁFA
A45: Méretbeli módosításra megrendeléstől számított 2 napon van belül lehetőseg! Ezután a méreteket elfogadottnak tekintjük, így méretek tekintetében reklamációt nem fogadunk el!
A47: Kiszállításnál sofőrünk egyedül megy, ezért a lepakoláshoz segitség szükséges! | F47: ÁRUKIADÁS: | H47: Hétfő - Péntek 7:30 - 16:00 Szombat 07:30 - 12:00
...

Sheet Kerités trapéz
A1: ELŐLEG | F1: Megrendelő
F2: Telefonszám
A3: VÉGÖSSZEG | F3: Szállítási cím
A4: Lemez | C4: Szín | D4: Felület | F4: Vastagság | G4: FILC! | H4: Nettó m2/egységár | J4: RSZ
A5: T18 - ECO Lengyel
B6: Teljes szélesség (m) | C6: Hosszúság (m) | D6: Db | E6: m2 összesen | F6: Egységár (nettó) | G6: Összesen (nettó) | H6: Összesen (bruttó) | J6: Rendelés
A7: 1. | B7: =VLOOKUP(A5,'Trapéz adatok'!A2:B17,2,FALSE) -> 0 | E7: =B7*C7*D7 -> 0 | F7: =$H$5 -> 0 | G7: =E7*F7 -> 0 | H7: =G7*1.27 -> 0 | J7: dátuma
A8: 2. | B8: =VLOOKUP(A5,'Trapéz adatok'!A2:B17,2,FALSE) -> 0 | E8: =B8*C8*D8 -> 0 | F8: =$H$5 -> 0 | G8: =E8*F8 -> 0 | H8: =G8*1.27 -> 0
A9: 3. | B9: =VLOOKUP(A5,'Trapéz adatok'!A2:B17,2,FALSE) -> 0 | E9: =B9*C9*D9 -> 0 | F9: =$H$5 -> 0 | G9: =E9*F9 -> 0 | H9: =G9*1.27 -> 0
A10: 4. | B10: =VLOOKUP(A5,'Trapéz adatok'!A2:B17,2,FALSE) -> 0 | E10: =B10*C10*D10 -> 0 | F10: =$H$5 -> 0 | G10: =E10*F10 -> 0 | H10: =G10*1.27 -> 0
A11: 5. | B11: =VLOOKUP(A5,'Trapéz adatok'!A2:B17,2,FALSE) -> 0 | E11: =B11*C11*D11 -> 0 | F11: =$H$5 -> 0 | G11: =E11*F11 -> 0 | H11: =G11*1.27 -> 0
A12: 6. | B12: =VLOOKUP(A5,'Trapéz adatok'!A2:B17,2,FALSE) -> 0 | E12: =B12*C12*D12 -> 0 | F12: =$H$5 -> 0 | G12: =E12*F12 -> 0 | H12: =G12*1.27 -> 0
A13: 7. | B13: =VLOOKUP(A5,'Trapéz adatok'!A2:B17,2,FALSE) -> 0 | E13: =B13*C13*D13 -> 0 | F13: =$H$5 -> 0 | G13: =E13*F13 -> 0 | H13: =G13*1.27 -> 0
A14: 8. | B14: =VLOOKUP(A5,'Trapéz adatok'!A2:B17,2,FALSE) -> 0 | E14: =B14*C14*D14 -> 0 | F14: =$H$5 -> 0 | G14: =E14*F14 -> 0 | H14: =G14*1.27 -> 0
A15: 9. | B15: =VLOOKUP(A5,'Trapéz adatok'!A2:B17,2,FALSE) -> 0 | E15: =B15*C15*D15 -> 0 | F15: =$H$5 -> 0 | G15: =E15*F15 -> 0 | H15: =G15*1.27 -> 0
A16: 10. | B16: =VLOOKUP(A5,'Trapéz adatok'!A2:B17,2,FALSE) -> 0 | E16: =B16*C16*D16 -> 0 | F16: =$H$5 -> 0 | G16: =E16*F16 -> 0 | H16: =G16*1.27 -> 0
A17: 11. | B17: =VLOOKUP(A5,'Trapéz adatok'!A2:B17,2,FALSE) -> 0 | E17: =B17*C17*D17 -> 0 | F17: =$H$5 -> 0 | G17: =E17*F17 -> 0 | H17: =G17*1.27 -> 0
A18: 12. | B18: =VLOOKUP(A5,'Trapéz adatok'!A2:B17,2,FALSE) -> 0 | E18: =B18*C18*D18 -> 0 | F18: =$H$5 -> 0 | G18: =E18*F18 -> 0 | H18: =G18*1.27 -> 0
A19: 13. | B19: =VLOOKUP(A5,'Trapéz adatok'!A2:B17,2,FALSE) -> 0 | E19: =B19*C19*D19 -> 0 | F19: =$H$5 -> 0 | G19: =E19*F19 -> 0 | H19: =G19*1.27 -> 0
A20: 14. | B20: =VLOOKUP(A5,'Trapéz adatok'!A2:B17,2,FALSE) -> 0 | E20: =B20*C20*D20 -> 0 | F20: =$H$5 -> 0 | G20: =E20*F20 -> 0 | H20: =G20*1.27 -> 0
A21: 15. | B21: =VLOOKUP(A5,'Trapéz adatok'!A2:B17,2,FALSE) -> 0 | E21: =B21*C21*D21 -> 0 | F21: =$H$5 -> 0 | G21: =E21*F21 -> 0 | H21: =G21*1.27 -> 0
A22: 16. | B22: =VLOOKUP(A5,'Trapéz adatok'!A2:B17,2,FALSE) -> 0 | E22: =B22*C22*D22 -> 0 | F22: =$H$5 -> 0 | G22: =E22*F22 -> 0 | H22: =G22*1.27 -> 0
A23: 17. | B23: =VLOOKUP(A5,'Trapéz adatok'!A2:B17,2,FALSE) -> 0 | E23: =B23*C23*D23 -> 0 | F23: =$H$5 -> 0 | G23: =E23*F23 -> 0 | H23: =G23*1.27 -> 0
A24: 18. | B24: =VLOOKUP(A5,'Trapéz adatok'!A2:B17,2,FALSE) -> 0 | E24: =B24*C24*D24 -> 0 | F24: =$H$5 -> 0 | G24: =E24*F24 -> 0 | H24: =G24*1.27 -> 0
A25: 19. | B25: =VLOOKUP(A5,'Trapéz adatok'!A2:B17,2,FALSE) -> 0 | E25: =B25*C25*D25 -> 0 | F25: =$H$5 -> 0 | G25: =E25*F25 -> 0 | H25: =G25*1.27 -> 0
A26: 20. | B26: =VLOOKUP(A5,'Trapéz adatok'!A2:B17,2,FALSE) -> 0 | E26: =B26*C26*D26 -> 0 | F26: =$H$5 -> 0 | G26: =E26*F26 -> 0 | H26: =G26*1.27 -> 0
B27: ÖSSZESEN: | E27: =SUM(E7:E26) -> 0 | F27: =$H$5 -> 0 | G27: =E27*F27 -> 0 | H27: =G27*1.27 -> 0
B28: TARTOZÉKOK
B29: Megnevezés | C29: db/m | D29: Egységár (nettó) | F29: Összesen (nettó) | H29: Összesen (bruttó)
B30: Fa csavar | D30: 19 | F30: =C30*D30 -> 0 | H30: =F30*1.27 -> 0
B31: Fém csavar | D31: 19 | F31: =C31*D31 -> 0 | H31: =F31*1.27 -> 0
B32: Szegő | D32: 15 | F32: =C32*D32 -> 0 | H32: =F32*1.27 -> 0
B33: Kis opel csavar | D33: 15 | F33: =C33*D33 -> 0 | H33: =F33*1.27 -> 0
B34: "J" szegő (m) | D34: 900 | F34: =C34*D34 -> 0 | H34: =F34*1.27 -> 0
B35: Kiszállítás | D35: 30000 | F35: =C35*D35 -> 0 | H35: =F35*1.27 -> 0
B36: ÖSSZESEN: | F36: =SUM(F30:F35) -> 0 | H36: =F36*1.27 -> 0
B38: ÖSSZESEN NETTÓ: | D38: =F36+G27 -> 0 | F38: ÖSSZESEN (bruttó) | H38: =D38*1.27 -> 0
B39: Fordított ÁFA
B41: ÁRUKIADÁS: | D41: Hétfő - Péntek 7:30 - 16:00 Szombat 07:30 - 12:00
A43: Figyelem! Az útmutatótól eltérő TÁROLÁSBÓL vagy anyagmozgatásból eredő károkért a ReCOPY Kft. (Simai úti lemezkereskedés) nem vállal felelősséget! Tárolási útmutató a hátoldalon!
...

Sheet Trapéz többféle
A1: ELŐLEG | F1: Megrendelő
F2: Telefonszám
A3: VÉGÖSSZEG | F3: Szállítási cím
A4: Lemez | C4: Szín | D4: Felület | F4: Vastagság | G4: FILC! | H4: Nettó m2/egységár | J4: RSZ
A5: T55 - Lengyel
B6: Teljes szélesség (m) | C6: Hosszúság (m) | D6: Db | E6: m2 összesen | F6: Egységár (nettó) | G6: Összesen (nettó) | H6: Összesen (bruttó) | J6: Rendelés
A7: 1. | B7: =VLOOKUP($A$5,'Trapéz adatok'!$A$2:$B$17,2,FALSE) -> 1.04 | E7: =B7*C7*D7 -> 0 | F7: =$H$5 -> 0 | G7: =E7*F7 -> 0 | H7: =G7*1.27 -> 0 | J7: dátuma
A8: 2. | B8: =VLOOKUP($A$5,'Trapéz adatok'!$A$2:$B$17,2,FALSE) -> 1.04 | E8: =B8*C8*D8 -> 0 | F8: =$H$5 -> 0 | G8: =E8*F8 -> 0 | H8: =G8*1.27 -> 0
A9: 3. | B9: =VLOOKUP($A$5,'Trapéz adatok'!$A$2:$B$17,2,FALSE) -> 1.04 | E9: =B9*C9*D9 -> 0 | F9: =$H$5 -> 0 | G9: =E9*F9 -> 0 | H9: =G9*1.27 -> 0
A10: 4. | B10: =VLOOKUP($A$5,'Trapéz adatok'!$A$2:$B$17,2,FALSE) -> 1.04 | E10: =B10*C10*D10 -> 0 | F10: =$H$5 -> 0 | G10: =E10*F10 -> 0 | H10: =G10*1.27 -> 0
A11: 5. | B11: =VLOOKUP($A$5,'Trapéz adatok'!$A$2:$B$17,2,FALSE) -> 1.04 | E11: =B11*C11*D11 -> 0 | F11: =$H$5 -> 0 | G11: =E11*F11 -> 0 | H11: =G11*1.27 -> 0
A12: 6. | B12: =VLOOKUP($A$5,'Trapéz adatok'!$A$2:$B$17,2,FALSE) -> 1.04 | E12: =B12*C12*D12 -> 0 | F12: =$H$5 -> 0 | G12: =E12*F12 -> 0 | H12: =G12*1.27 -> 0
A13: 7. | B13: =VLOOKUP($A$5,'Trapéz adatok'!$A$2:$B$17,2,FALSE) -> 1.04 | E13: =B13*C13*D13 -> 0 | F13: =$H$5 -> 0 | G13: =E13*F13 -> 0 | H13: =G13*1.27 -> 0
A14: 8. | B14: =VLOOKUP($A$5,'Trapéz adatok'!$A$2:$B$17,2,FALSE) -> 1.04 | E14: =B14*C14*D14 -> 0 | F14: =$H$5 -> 0 | G14: =E14*F14 -> 0 | H14: =G14*1.27 -> 0
B15: ÖSSZESEN: | E15: =SUM(E7:E14) -> 0 | F15: =$H$5 -> 0 | G15: =E15*F15 -> 0 | H15: =G15*1.27 -> 0
A17: Lemez | C17: Szín | D17: Felület | F17: Vastagság | G17: FILC! | H17: Nettó m2/egységár
A18: T8 Saját gyártású
B19: Teljes szélesség (m) | C19: Hosszúság (m) | D19: Db | E19: m2 összesen | F19: Egységár (nettó) | G19: Összesen (nettó) | H19: Összesen (bruttó)
A20: 1. | B20: =VLOOKUP($A$18,'Trapéz adatok'!$A$2:$B$17,2,FALSE) -> 1.18 | E20: =B20*C20*D20 -> 0 | F20: =$H$18 -> 0 | G20: =E20*F20 -> 0 | H20: =G20*1.27 -> 0
A21: 2. | B21: =VLOOKUP($A$18,'Trapéz adatok'!$A$2:$B$17,2,FALSE) -> 1.18 | E21: =B21*C21*D21 -> 0 | F21: =$H$18 -> 0 | G21: =E21*F21 -> 0 | H21: =G21*1.27 -> 0
A22: 3. | B22: =VLOOKUP($A$18,'Trapéz adatok'!$A$2:$B$17,2,FALSE) -> 1.18 | E22: =B22*C22*D22 -> 0 | F22: =$H$18 -> 0 | G22: =E22*F22 -> 0 | H22: =G22*1.27 -> 0
A23: 4. | B23: =VLOOKUP($A$18,'Trapéz adatok'!$A$2:$B$17,2,FALSE) -> 1.18 | E23: =B23*C23*D23 -> 0 | F23: =$H$18 -> 0 | G23: =E23*F23 -> 0 | H23: =G23*1.27 -> 0
A24: 5. | B24: =VLOOKUP($A$18,'Trapéz adatok'!$A$2:$B$17,2,FALSE) -> 1.18 | E24: =B24*C24*D24 -> 0 | F24: =$H$18 -> 0 | G24: =E24*F24 -> 0 | H24: =G24*1.27 -> 0
A25: 6. | B25: =VLOOKUP($A$18,'Trapéz adatok'!$A$2:$B$17,2,FALSE) -> 1.18 | E25: =B25*C25*D25 -> 0 | F25: =$H$18 -> 0 | G25: =E25*F25 -> 0 | H25: =G25*1.27 -> 0
A26: 7. | B26: =VLOOKUP($A$18,'Trapéz adatok'!$A$2:$B$17,2,FALSE) -> 1.18 | E26: =B26*C26*D26 -> 0 | F26: =$H$18 -> 0 | G26: =E26*F26 -> 0 | H26: =G26*1.27 -> 0
A27: 8. | B27: =VLOOKUP($A$18,'Trapéz adatok'!$A$2:$B$17,2,FALSE) -> 1.18 | E27: =B27*C27*D27 -> 0 | F27: =$H$18 -> 0 | G27: =E27*F27 -> 0 | H27: =G27*1.27 -> 0
B28: ÖSSZESEN: | E28: =SUM(E20:E27) -> 0 | F28: =$H$18 -> 0 | G28: =E28*F28 -> 0 | H28: =G28*1.27 -> 0
B30: TARTOZÉKOK
B31: Megnevezés | C31: db/m | D31: Egységár (nettó) | F31: Összesen (nettó) | H31: Összesen (bruttó)
B32: Kupás 14x14 | F32: =C32*D32 -> 0 | H32: =F32*1.27 -> 0
B33: Síklemez | F33: =C33*D33 -> 0 | H33: =F33*1.27 -> 0
B34: Fa csavar | F34: =C34*D34 -> 0 | H34: =F34*1.27 -> 0
B35: Fém csavar | F35: =C35*D35 -> 0 | H35: =F35*1.27 -> 0
B36: Fűző csavar | F36: =C36*D36 -> 0 | H36: =F36*1.27 -> 0
B37: Tetőfólia | F37: =C37*D37 -> 0 | H37: =F37*1.27 -> 0
B38: Profil szivacs | F38: =C38*D38 -> 0 | H38: =F38*1.27 -> 0
B39: Kéményszegő | F39: =C39*D39 -> 0 | H39: =F39*1.27 -> 0
B40: Villanyszegő | F40: =C40*D40 -> 0 | H40: =F40*1.27 -> 0
B41: Hóvágó | F41: =C41*D41 -> 0 | H41: =F41*1.27 -> 0
B42: Oromszegő | F42: =C42*D42 -> 0 | H42: =F42*1.27 -> 0
...

Sheet Trapéz + kerítéselem
A1: ELŐLEG | F1: Megrendelő
F2: Telefonszám
A3: VÉGÖSSZEG | F3: Szállítási cím
A4: Kerítéselem | C4: Szín | D4: Felület | F4: Méret | H4: Nettó m2/egységár | J4: RSZ
H5: 500
B6: Hosszúság (m) | C6: Db | D6: m összesen | E6: Egységár (nettó) | F6: Összesen (nettó) | G6: Összesen (bruttó) | J6: Rendelés
A7: 1. | D7: =B7*C7 -> 0 | E7: =$H$5 -> 500 | F7: =D7*E7 -> 0 | G7: =F7*1.27 -> 0 | J7: dátuma
A8: 2. | D8: =B8*C8 -> 0 | E8: =$H$5 -> 500 | F8: =D8*E8 -> 0 | G8: =F8*1.27 -> 0
A9: 3. | D9: =B9*C9 -> 0 | E9: =$H$5 -> 500 | F9: =D9*E9 -> 0 | G9: =F9*1.27 -> 0
A10: 4. | D10: =B10*C10 -> 0 | E10: =$H$5 -> 500 | F10: =D10*E10 -> 0 | G10: =F10*1.27 -> 0
A11: 5. | D11: =B11*C11 -> 0 | E11: =$H$5 -> 500 | F11: =D11*E11 -> 0 | G11: =F11*1.27 -> 0
A12: 6. | D12: =B12*C12 -> 0 | E12: =$H$5 -> 500 | F12: =D12*E12 -> 0 | G12: =F12*1.27 -> 0
A13: 7. | D13: =B13*C13 -> 0 | E13: =$H$5 -> 500 | F13: =D13*E13 -> 0 | G13: =F13*1.27 -> 0
A14: 8. | D14: =B14*C14 -> 0 | E14: =$H$5 -> 500 | F14: =D14*E14 -> 0 | G14: =F14*1.27 -> 0
A15: 9. | D15: =B15*C15 -> 0 | E15: =$H$5 -> 500 | F15: =D15*E15 -> 0 | G15: =F15*1.27 -> 0
A16: 10. | D16: =B16*C16 -> 0 | E16: =$H$5 -> 500 | F16: =D16*E16 -> 0 | G16: =F16*1.27 -> 0
A17: 11. | D17: =B17*C17 -> 0 | E17: =$H$5 -> 500 | F17: =D17*E17 -> 0 | G17: =F17*1.27 -> 0
A18: 12. | D18: =B18*C18 -> 0 | E18: =$H$5 -> 500 | F18: =D18*E18 -> 0 | G18: =F18*1.27 -> 0
B19: ÖSSZESEN: | D19: =SUM(D7:D18) -> 0 | F19: =SUM(F7:F18) -> 0 | G19: =F19*1.27 -> 0
A21: "U" PROFILOK
B22: Hosszúság (m) | C22: Db | D22: (m) összesen | E22: Egységár (nettó) | F22: Összesen (nettó) | G22: Összesen (bruttó)
A23: 1. | D23: =B23*C23 -> 0 | E23: 0 | F23: =D23*E23 -> 0 | G23: =F23*1.27 -> 0
A24: 2. | D24: =B24*C24 -> 0 | E24: 0 | F24: =D24*E24 -> 0 | G24: =F24*1.27 -> 0
A25: 3. | D25: =B25*C25 -> 0 | E25: 0 | F25: =D25*E25 -> 0 | G25: =F25*1.27 -> 0
A26: 4. | D26: =B26*C26 -> 0 | E26: 0 | F26: =D26*E26 -> 0 | G26: =F26*1.27 -> 0
A27: 5. | D27: =B27*C27 -> 0 | E27: 0 | F27: =D27*E27 -> 0 | G27: =F27*1.27 -> 0
A28: 6. | D28: =B28*C28 -> 0 | E28: 0 | F28: =D28*E28 -> 0 | G28: =F28*1.27 -> 0
A29: 7. | D29: =B29*C29 -> 0 | E29: 0 | F29: =D29*E29 -> 0 | G29: =F29*1.27 -> 0
B30: ÖSSZESEN: | D30: =SUM(D23:D29) -> 0 | E30: 0 | F30: =D30*E30 -> 0 | G30: =F30*1.27 -> 0
A32: Lemez | C32: Szín | D32: Felület | F32: Vastagság | G32: FILC! | H32: Nettó m2/egységár
A33: T8 Saját gyártású | H33: 500
B34: Teljes szélesség (m) | C34: Hosszúság (m) | D34: Db | E34: m2 összesen | F34: Egységár (nettó) | G34: Összesen (nettó) | H34: Összesen (bruttó)
A35: 1. | B35: =VLOOKUP($A$33,'Trapéz adatok'!$A$2:$B$17,2,FALSE) -> 1.18 | E35: =B35*C35*D35 -> 0 | F35: =$H$33 -> 500 | G35: =E35*F35 -> 0 | H35: =G35*1.27 -> 0
A36: 2. | B36: =VLOOKUP($A$33,'Trapéz adatok'!$A$2:$B$17,2,FALSE) -> 1.18 | E36: =B36*C36*D36 -> 0 | F36: =$H$33 -> 500 | G36: =E36*F36 -> 0 | H36: =G36*1.27 -> 0
A37: 3. | B37: =VLOOKUP($A$33,'Trapéz adatok'!$A$2:$B$17,2,FALSE) -> 1.18 | E37: =B37*C37*D37 -> 0 | F37: =$H$33 -> 500 | G37: =E37*F37 -> 0 | H37: =G37*1.27 -> 0
A38: 4. | B38: =VLOOKUP($A$33,'Trapéz adatok'!$A$2:$B$17,2,FALSE) -> 1.18 | E38: =B38*C38*D38 -> 0 | F38: =$H$33 -> 500 | G38: =E38*F38 -> 0 | H38: =G38*1.27 -> 0
A39: 5. | B39: =VLOOKUP($A$33,'Trapéz adatok'!$A$2:$B$17,2,FALSE) -> 1.18 | E39: =B39*C39*D39 -> 0 | F39: =$H$33 -> 500 | G39: =E39*F39 -> 0 | H39: =G39*1.27 -> 0
A40: 6. | B40: =VLOOKUP($A$33,'Trapéz adatok'!$A$2:$B$17,2,FALSE) -> 1.18 | E40: =B40*C40*D40 -> 0 | F40: =$H$33 -> 500 | G40: =E40*F40 -> 0 | H40: =G40*1.27 -> 0
A41: 7. | B41: =VLOOKUP($A$33,'Trapéz adatok'!$A$2:$B$17,2,FALSE) -> 1.18 | E41: =B41*C41*D41 -> 0 | F41: =$H$33 -> 500 | G41: =E41*F41 -> 0 | H41: =G41*1.27 -> 0
A42: 8. | B42: =VLOOKUP($A$33,'Trapéz adatok'!$A$2:$B$17,2,FALSE) -> 1.18 | E42: =B42*C42*D42 -> 0 | F42: =$H$33 -> 500 | G42: =E42*F42 -> 0 | H42: =G42*1.27 -> 0
...

Sheet Keritéselemek
A1: ELŐLEG | F1: Megrendelő
F2: Telefonszám
A3: VÉGÖSSZEG | F3: Szállítási cím
A4: Kerítéselem | C4: Szín | D4: Felület | F4: Méret | H4: Nettó m2/egységár | J4: RSZ
B6: Hosszúság (m) | C6: Db | D6: (m) összesen | E6: Egységár (nettó) | F6: Összesen (nettó) | G6: Összesen (bruttó) | J6: Rendelés
A7: 1. | D7: =B7*C7 -> 0 | E7: =$H$5 -> 0 | F7: =D7*E7 -> 0 | G7: =F7*1.27 -> 0 | J7: dátuma
A8: 2. | D8: =B8*C8 -> 0 | E8: =$H$5 -> 0 | F8: =D8*E8 -> 0 | G8: =F8*1.27 -> 0
A9: 3. | D9: =B9*C9 -> 0 | E9: =$H$5 -> 0 | F9: =D9*E9 -> 0 | G9: =F9*1.27 -> 0
A10: 4. | D10: =B10*C10 -> 0 | E10: =$H$5 -> 0 | F10: =D10*E10 -> 0 | G10: =F10*1.27 -> 0
A11: 5. | D11: =B11*C11 -> 0 | E11: =$H$5 -> 0 | F11: =D11*E11 -> 0 | G11: =F11*1.27 -> 0
A12: 6. | D12: =B12*C12 -> 0 | E12: =$H$5 -> 0 | F12: =D12*E12 -> 0 | G12: =F12*1.27 -> 0
A13: 7. | D13: =B13*C13 -> 0 | E13: =$H$5 -> 0 | F13: =D13*E13 -> 0 | G13: =F13*1.27 -> 0
A14: 8. | D14: =B14*C14 -> 0 | E14: =$H$5 -> 0 | F14: =D14*E14 -> 0 | G14: =F14*1.27 -> 0
A15: 9. | D15: =B15*C15 -> 0 | E15: =$H$5 -> 0 | F15: =D15*E15 -> 0 | G15: =F15*1.27 -> 0
A16: 10. | D16: =B16*C16 -> 0 | E16: =$H$5 -> 0 | F16: =D16*E16 -> 0 | G16: =F16*1.27 -> 0
A17: 11. | D17: =B17*C17 -> 0 | E17: =$H$5 -> 0 | F17: =D17*E17 -> 0 | G17: =F17*1.27 -> 0
A18: 12. | D18: =B18*C18 -> 0 | E18: =$H$5 -> 0 | F18: =D18*E18 -> 0 | G18: =F18*1.27 -> 0
A19: 13. | D19: =B19*C19 -> 0 | E19: =$H$5 -> 0 | F19: =D19*E19 -> 0 | G19: =F19*1.27 -> 0
... A21: 15. | D21: =B21*C21 -> 0 | E21: =$H$5 -> 0 | F21: =D21*E21 -> 0 | G21: =F21*1.27 -> 0
B22: ÖSSZESEN: | D22: =SUM(D7:D21) -> 0 | E22: =$H$5 -> 0 | F22: =SUM(F7:F21) -> 0 | G22: =F22*1.27 -> 0
A23: "U" PROFILOK
B24: Hosszúság (m) | C24: Db | D24: m összesen | E24: Egységár (nettó) | F24: Összesen (nettó) | G24: Összesen (bruttó)
A25: 1. | D25: =B25*C25 -> 0 | E25: 1800 | F25: =D25*E25 -> 0 | G25: =F25*1.27 -> 0
A26: 2. | D26: =B26*C26 -> 0 | E26: 1800 | F26: =D26*E26 -> 0 | G26: =F26*1.27 -> 0
A27: 3. | D27: =B27*C27 -> 0 | E27: 1800 | F27: =D27*E27 -> 0 | G27: =F27*1.27 -> 0
A28: 4. | D28: =B28*C28 -> 0 | E28: 1800 | F28: =D28*E28 -> 0 | G28: =F28*1.27 -> 0
A29: 5. | D29: =B29*C29 -> 0 | E29: 1800 | F29: =D29*E29 -> 0 | G29: =F29*1.27 -> 0 | H29: ÁRUKIADÁS:
A30: 6. | D30: =B30*C30 -> 0 | E30: 1800 | F30: =D30*E30 -> 0 | G30: =F30*1.27 -> 0
A31: 7. | D31: =B31*C31 -> 0 | E31: 1800 | F31: =D31*E31 -> 0 | G31: =F31*1.27 -> 0 | H31: Hétfő - Péntek 7:30 - 16:00 Szombat 07:30 - 12:00
B32: ÖSSZESEN: | D32: =SUM(D25:D31) -> 0 | E32: 1800 | F32: =D32*E32 -> 0 | G32: =F32*1.27 -> 0
B33: TARTOZÉKOK
B34: Megnevezés | C34: db/m | D34: Egységár (nettó) | F34: Összesen (nettó) | H34: Összesen (bruttó)
B35: Fém csavar | D35: 19 | F35: =C35*D35 -> 0 | H35: =F35*1.27 -> 0
B36: Nagy opel csav. | D36: 17 | F36: =C36*D36 -> 0 | H36: =F36*1.27 -> 0
B37: Kis opel csav. | D37: 15 | F37: =C37*D37 -> 0 | H37: =F37*1.27 -> 0
B38: Rögzítő lapka | D38: 0 | F38: =C38*D38 -> 0 | H38: =F38*1.27 -> 0
B39: ÖSSZESEN: | F39: =SUM(F35:F38) -> 0 | H39: =F39*1.27 -> 0
B41: ÖSSZESEN NETTÓ: | D41: =F22+F32+F39 -> 0 | F41: ÖSSZESEN (bruttó) | H41: =D41*1.27 -> 0
B42: Fordított ÁFA
A43: Figyelem! Az útmutatótól eltérő TÁROLÁSBÓL vagy anyagmozgatásból eredő károkért a ReCOPY Kft. (Simai úti lemezkereskedés) nem vállal felelősséget! Tárolási útmutató a hátoldalon!
...

Sheet Cserepes adatok
A1: Név | B1: Teljes szélesség | D1: Szélességek | F1: Felület | H1: FILC | J1: Szín
A2: Amalfi Plus | B2: 1.2 | D2: 0,4 mm | F2: Fényes | H2: IGEN! | J2: 3000
A3: Beskid Plus | B3: 1.2 | D3: 0,45 mm | F3: MATT | H3: NEM! | J3: 3005
A4: Bona Plus | B4: 1.19 | D4: 0,5 mm | F4: ULTRA Matt | J4: 3009
A5: Lima Plus | B5: 1.202 | D5: 0,6 mm | F5: Standard matt | J5: 3011
A6: Perla Plus | B6: 1.15 | D6: 0,7 mm | J6: 5010
A7: Hexa | B7: 1.23 | J7: 6005
A8: PDT-19 | B8: 1.095 | J8: 6011
A9: PD-28/540 | B9: 0.54 | J9: 6020
J10: 7016
J11: 7024
J12: 7035
J13: 8004
J14: 8017
J15: 8019
J16: 9002
J17: 9005
J18: 9006
J19: 9007
J20: 9010

Sheet Trapéz adatok
A1: Név | B1: Teljes szélesség | D1: Szélességek | F1: Felület | H1: FILC | J1: Szín
A2: T8 - Lengyel | B2: 1.19 | D2: 0,38 mm | F2: Fényes | H2: IGEN! | J2: 1002
A3: T8 Saját gyártású | B3: 1.18 | D3: 0,4 mm | F3: MATT | H3: NEM! | J3: 1015
A4: T8 - MS | B4: 1.18 | D4: 0,45 mm | F4: ULTRA Matt | J4: 3000
A5: T14 Saját gyártású | B5: 1.1 | D5: 0,5 mm | F5: Standard matt | J5: 3005
A6: T14 - Lengyel | B6: 1.16 | D6: 0,6 mm | F6: Fényes 2 oldalas | J6: 3009
A7: T18 - Lengyel | B7: 1.14 | D7: 0,7 mm | F7: Matt 2 oldalas | J7: 3011
A8: T18 - ECO Lengyel | F8: Egyoldalas | J8: 5010
A9: T18 Saját gyártású | B9: 1.15 | F9: Kétoldalas | J9: 6005
A10: T20/1120 MS | B10: 1.12 | F10: Multigloss 1 oldalas | J10: 6011
A11: T20/1160 MS | B11: 1.16 | F11: Multigloss 2 oldalas | J11: 6020
A12: T35 Saját gyártású | B12: 1.05 | F12: Sötét - egyoldalas | J12: 7016
A13: T35 - Lengyel | B13: 1.08 | F13: Világos -egyoldalas | J13: 7024
A14: T38 - MS | B14: 1.1 | F14: Sötét -kétoldalas | J14: 7035
A15: T45 - MS | B15: 1.05 | J15: 8004
A16: T50 - MS | B16: 1.08 | J16: 8017
A17: T55 - Lengyel | B17: 1.04 | J17: 8019
J18: 9002
J19: 9005
J20: 9006
J21: 9007
J22: 9010
J23: Alucink
J24: Antracit famintás
J25: Aranytölgy
J26: Aranytölgy -L
J27: Cseresznye
J28: Dió
J29: Dió - L
J30: Fenyő
J31: Horganyzott
J32: Mézéger
J33: Sonoma
J34: Winchester

Sheet Keritésadatok
A1: Név | C1: Méretek | E1: Felület | G1: Szín
A2: Elite kerítéselem | C2: 7,5 cm | E2: Fényes | G2: 1002
A3: C-profil (erősített) | C3: 8 cm | E3: MATT | G3: 1015
A4: Lamellás kerítéselem | C4: 8,5 cm | E4: ULTRA Matt | G4: 3000
A5: Dobozos kerítéselem | C5: 10 cm | E5: Standard matt | G5: 3005
A6: Shadora kerítéselem | C6: 11 cm | E6: Fényes 1 oldalas | G6: 3009
A7: Lumea kerítéselem | C7: 12 cm | E7: Fényes 2 oldalas | G7: 3011
A8: Pergolis kerítéselem | C8: 14 cm | E8: Matt 2 oldalas | G8: 5010
A9: Íves domború | C9: 15 cm | E9: Egyoldalas | G9: 6005
A10: Íves lapos | C10: 16 cm | E10: Kétoldalas | G10: 6011
C11: 11 cm - íves domború | E11: Multigloss 1 oldalas | G11: 6020
C12: 11,6 cm - íves lapos | E12: Multigloss 2 oldalas | G12: 7016
E13: Sötét - egyoldalas | G13: 7024
E14: Világos -egyoldalas | G14: 7035
E15: Sötét -kétoldalas | G15: 8004
G16: 8017
G17: 8019
G18: 9002
G19: 9005
G20: 9006
G21: 9007
G22: 9010
G23: Alucink
G24: Antracit famintás
G25: Aranytölgy
G26: Aranytölgy -L
G27: Cseresznye
G28: Dió
G29: Dió - L
G30: Fenyő
G31: Horganyzott
G32: Mézéger
G33: Sonoma
G34: Winchester
